Workbook

Sheet Hướng dẫn
A1: VClinks — Chi phí phát triển, duy trì và hạ tầng
B2: v0.7 · 05/10/2026. Diễn giải: docs/01-quan-ly-du-an/chi-phi-phat-trien.md. Sheet "Dự báo lại" (mới 05/10/2026) tính lại theo cách làm thực tế: chủ dự án điều phối agent, không có 2 dev
A3: Phiên bản | B3: v0.4 · 04/10/2026. Diễn giải: docs/ke-hoach/chi-phi-phat-trien.md
A4: Căn cứ phạm vi | B4: docs/ba/vclinks-ba.md §19 Lộ trình, §20 Rủi ro. Thứ tự làm theo chủ dự án (04/10/2026): M1 → M3 → M2 → M4
A5: Đã chốt (04/10/2026) | B5: 2 dev, lương 75 triệu/tháng đã gồm mọi khoản; máy chủ thuê cloud toàn bộ; lưu lượng 30 người dùng, 3.000 tin/ngày, 40% tin soạn nháp; gói Zalo OA 3 triệu/năm; dùng Claude Code Max; mốc 2 tháng, Zalo cá nhân 3 ngày, Khách hàng 360 2 ngày (= kịch bản Lạc quan). M1 → M3 → M2 chỉ làm trên Zalo cá nhân; mọi kênh khác ở M4, mỗi kênh 4 ngày, 2 dev làm song song 2 kênh
A7: Ba nhóm chi phí | B7: PHÁT TRIỂN (một lần): lương dev, BA, thiết kế giao diện, Claude Code Max trong thời gian làm. DUY TRÌ (hằng tháng sau khi chạy thật): bảo trì, BA thu góp ý, Claude Code Max cho bảo trì. HẠ TẦNG: cloud (môi trường thử khi phát triển, môi trường thật khi chạy), Claude API, Zalo OA.
A8: Ba kịch bản | B8: Lạc quan = mốc chủ dự án. Trung bình và Tiêu cực kéo dài thời gian, tăng BA/thiết kế, bảo trì và cấu hình cloud. Kịch bản đã gồm rủi ro nên không cộng thêm % dự phòng.
A10: Quy ước màu
A11: Chữ xanh dương | B11: Số nhập tay
A12: Nền vàng | B12: Giả định còn chờ xác nhận (báo giá cloud, lương BA/thiết kế, thông số kịch bản)
A13: Chữ đen | B13: Công thức — không sửa
A14: Chữ xanh lá | B14: Lấy từ sheet khác
A16: Cách dùng | B16: 1) Sửa thông số kịch bản ở 'Kịch bản'. 2) Sửa lương, giá ở 'Tham số'. 3) Sửa báo giá cloud ở 'Hạ tầng'. 4) Đọc 'Tổng hợp' và 'Tiến độ'. 'Khối lượng' là ngày công ước lượng nếu không dùng AI, dùng để chia thời gian giữa các mảnh và tính tốc độ cần.
A17: Không tính | B17: Phần đã làm tới 04/10/2026 (code nền, VC Zalo UAT 13/13, bộ đặc tả BA 00–07) — chi phí chìm. Công của chủ dự án duyệt. Chi phí phía ERP để VCsales/VCinvoice mở API.

Sheet Dự báo lại
A1: Dự báo lại theo cách làm thực tế (05/10/2026)
A2: Cách làm thực tế: 2 dev dùng AI viết 100% code (chủ dự án xác nhận 05/10/2026), chạy tối đa 5 agent Claude Code song song; chủ dự án điều phối và duyệt. Ba kịch bản cũ ở sheet Tổng hợp giữ để đối chiếu.
A4: 1. Số đo M1 (đến 05/10/2026 05:00) | B4: Kế hoạch | C4: Thực tế | D4: Chênh | E4: Đơn vị | F4: Nguồn
A5: Số phiên code M1 | B5: 34 | C5: 38 | D5: =C5-B5 | E5: phiên | F5: Sổ phiên: thêm M1b-17, M1b-18 (sửa lỗi UAT), M1c-11, M1c-12
A6: Phiên đã gộp vào main | C6: 33 | E6: phiên | F6: 33 ✅ + 1 🟡 (M1c-08); còn M1a-07, M1c-11, M1c-12, M1c-10
A7: Giờ máy cho các phiên đã gộp | B7: 137 | E7: giờ | F7: Kế hoạch §4.3 cộng giờ máy của 33 phiên ✅ (M1b-17, 18 không có trong kế hoạch). Bảng §4.3 cộng đủ 34 phiên gốc là 154 giờ, lệch với số 107 giờ ở Tóm tắt kế hoạch
A8: Thời gian chạy thực (từ 15:00 04/10 đến 00:17 05/10) | C8: 9.5 | E8: giờ | F8: Git log: M1-00 commit 15:05, đợt 5–7 gộp xong 00:17
A9: Tốc độ so với kế hoạch | C9: =B7/C8 | E9: lần | F9: Giờ máy kế hoạch ÷ giờ chạy thực (5 agent song song)
A10: Lượt gọi model trong M1 (Opus / Sonnet / Fable) | C10: 3.428 / 1.767 / 37 | E10: lượt | F10: Nhật ký Claude Code trên máy, 04/10 13:00 → 05/10 05:00
A11: % hạn mức tuần đã dùng | C11: 8% (đầu đợt 1) | E11: % | F11: Nhật ký nhịp; cuối đợt 5–7 chưa đọc /usage
A12: Phiên còn ⛔ một phần (chờ đầu vào ngoài hoặc chủ dự án thử tay) | C12: 27 | E12: phiên | F12: Nút thắt không còn là code mà là E1–E8, thử tay, UAT
A14: 2. Thông số ba kịch bản mới | B14: Lạc quan | C14: Trung bình | D14: Tiêu cực | E14: Đơn vị | F14: Ghi chú
A15: Thời gian hoàn thiện M1 → M4 | B15: 1.5 | C15: 1.75 | D15: 3 | E15: tháng | F15: Do thời gian chờ đầu vào (API ERP, UAT), không do code. Meta App Review và Zalo OA Open API tạm tính 1 ngày (chủ dự án 05/10/2026)
A16: Suất Claude Code Max khi phát triển | B16: 3 | C16: 3 | D16: 3 | E16: suất | F16: 2 dev + chủ dự án điều phối (chủ dự án đồng ý 05/10/2026)
A17: Người kiểm thử / BA (% của lương BA) | B17: 0 | C17: 0.25 | D17: 0.5 | E17: % thời gian | F17: 2 dev tự thử tay và chạy UAT (chủ dự án đồng ý 05/10/2026)
A18: Thiết kế giao diện (% của lương thiết kế) | B18: 0 | C18: 0.25 | D18: 0.5 | E18: % thời gian | F18: Lạc quan: Claude vẽ canvas, chủ dự án duyệt
A19: Suất Claude Code Max khi duy trì | B19: 1 | C19: 1 | D19: 2 | E19: suất
A20: BA / kiểm thử khi duy trì | B20: 0.1 | C20: 0.2 | D20: 0.3 | E20: % thời gian | F20: Thu góp ý, thử bản sửa
A21: Hệ số cấu hình cloud | B21: ='Kịch bản'!B14 | C21: ='Kịch bản'!C14 | D21: ='Kịch bản'!D14 | E21: hệ số | F21: Lấy từ Kịch bản
A23: 3. Chi phí (VNĐ) | B23: Lạc quan | C23: Trung bình | D23: Tiêu cực | F23: Cách tính
A24: Claude Code Max khi phát triển | B24: ='Tham số'!$B$13*B16*B15 | C24: ='Tham số'!$B$13*C16*C15 | D24: ='Tham số'!$B$13*D16*D15 | F24: Suất × giá suất × tháng
A25: Người kiểm thử / BA | B25: ='Tham số'!$B$9*B17*B15 | C25: ='Tham số'!$B$9*C17*C15 | D25: ='Tham số'!$B$9*D17*D15 | F25: Lương BA × % × tháng
A26: Thiết kế giao diện | B26: ='Tham số'!$B$10*B18*B15 | C26: ='Tham số'!$B$10*C18*C15 | D26: ='Tham số'!$B$10*D18*D15 | F26: Lương thiết kế × % × tháng
A27: Lương dev | B27: ='Tham số'!$B$6*B15 | C27: ='Tham số'!$B$6*C15 | D27: ='Tham số'!$B$6*D15 | F27: Lương 2 dev (75 triệu/tháng) × tháng; dev dùng AI viết 100% code
A28: A. Cộng phát triển | B28: =SUM(B24:B27) | C28: =SUM(C24:C27) | D28: =SUM(D24:D27)
A29: Hạ tầng thử trong giai đoạn phát triển | B29: ='Hạ tầng'!$B$15*B21*'Hạ tầng'!$B$16*B15 | C29: ='Hạ tầng'!$B$15*C21*'Hạ tầng'!$B$16*C15 | D29: ='Hạ tầng'!$B$15*D21*'Hạ tầng'!$B$16*D15 | F29: Cloud × hệ số × 50% × tháng
A30: Claude Code Max cho duy trì | B30: ='Tham số'!$B$13*B19 | C30: ='Tham số'!$B$13*C19 | D30: ='Tham số'!$B$13*D19
A31: Bảo trì dev + BA / kiểm thử khi duy trì | B31: ='Kịch bản'!B11*'Tham số'!$B$8+'Tham số'!$B$9*B20 | C31: ='Kịch bản'!C11*'Tham số'!$B$8+'Tham số'!$B$9*C20 | D31: ='Kịch bản'!D11*'Tham số'!$B$8+'Tham số'!$B$9*D20 | F31: Ngày công bảo trì (Kịch bản: 5 / 8 / 12) × đơn giá ngày dev + lương BA × %
A32: B. Cộng duy trì / tháng | B32: =SUM(B30:B31) | C32: =SUM(C30:C31) | D32: =SUM(D30:D31)
A33: C. Hạ tầng chạy thật / tháng | B33: ='Tổng hợp'!B27 | C33: ='Tổng hợp'!C27 | D33: ='Tổng hợp'!D27 | F33: Như ba kịch bản cũ (cloud + Claude API + Zalo OA)
A34: TỔNG NĂM ĐẦU (phát triển + 12 tháng chạy thật) | B34: =B28+B29+12*(B32+B33) | C34: =C28+C29+12*(C32+C33) | D34: =D28+D29+12*(D32+D33)
A35: Tổng năm đầu theo ba kịch bản cũ (2 dev, 2 / 3 / 4 tháng) | B35: ='Tổng hợp'!B34 | C35: ='Tổng hợp'!C34 | D35: ='Tổng hợp'!D34 | F35: Sheet Tổng hợp
A36: Giảm so với kịch bản cũ | B36: =1-B34/B35 | C36: =1-C34/C35 | D36: =1-D34/D35 | E36: %
A37: Chi phí mỗi tháng sau khi hoàn thiện | B37: =B32+B33 | C37: =C32+C33 | D37: =D32+D33 | F37: Duy trì + hạ tầng
A38: Mỗi tháng trễ mốc tốn thêm | B38: =(B28+B29)/B15 | C38: =(C28+C29)/C15 | D38: =(D28+D29)/D15 | F38: (Phát triển + hạ tầng thử) ÷ tháng
A40: 4. Mốc theo mảnh | B40: Lạc quan | C40: Trung bình | D40: Tiêu cực | E40: Phiên ước | F40: Điều kiện quyết định thời gian
A41: M1 code (38 phiên) | B41: 06/10/2026 | C41: 06/10/2026 | D41: 07/10/2026 | E41: 38 | F41: Còn 5 phiên; code không phải nút thắt
A42: M1 chạy thật với đội VCparts | B42: 15/10/2026 | C42: 26/10/2026 | D42: 02/11/2026 | F42: E2 nick công ty, E5 API VCsales, E6 thiết kế MH-SZ-15, E7 quyết định, E8 API key; chủ dự án thử tay 27 phiên ⛔ một phần; UAT
A43: M3 · 360 đủ, hóa đơn, app điện thoại | B43: 07/10 – 23/10 | C43: 12/10 – 06/11 | D43: 19/10 – 20/11 | E43: 20 | F43: Code song song lúc chờ M1. API VCsales / VCinvoice / VCdms (TT-01, 05, 06), QĐ-01 app
A44: M2 · phân luồng AI, giám sát, L6–L7 | B44: 26/10 – 06/11 | C44: 09/11 – 20/11 | D44: 23/11 – 11/12 | E44: 16 | F44: Cần dữ liệu thật từ 2 tuần baseline sau M1; NĐ 13
...

Sheet Tổng hợp
A1: Tổng hợp chi phí — ba kịch bản
A2: Phát triển = một lần. Duy trì và hạ tầng chạy thật = hằng tháng sau khi hoàn thiện. Năm đầu = phát triển + 12 tháng chạy thật.
A4: Khoản (VNĐ) | B4: Lạc quan | C4: Trung bình | D4: Tiêu cực | E4: Cách tính
A5: Thời gian hoàn thiện (tháng) | B5: ='Kịch bản'!$B$4 | C5: ='Kịch bản'!$C$4 | D5: ='Kịch bản'!$D$4 | E5: Sheet Kịch bản
A6: M1 xong | B6: ='Tiến độ'!E14 | C6: ='Tiến độ'!H14 | D6: ='Tiến độ'!K14 | E6: Sheet Tiến độ
A7: Hoàn thiện M4 | B7: ='Tiến độ'!E12 | C7: ='Tiến độ'!H12 | D7: ='Tiến độ'!K12 | E7: Sheet Tiến độ
A8: Tốc độ cần so với không dùng AI | B8: ='Tiến độ'!C15 | C8: ='Tiến độ'!F15 | D8: ='Tiến độ'!I15 | E8: Sheet Tiến độ
A10: A. PHÁT TRIỂN (một lần)
A11: Lương 2 dev | B11: ='Tham số'!$B$6*B5 | C11: ='Tham số'!$B$6*C5 | D11: ='Tham số'!$B$6*D5 | E11: Lương đội × tháng
A12: BA | B12: ='Tham số'!$B$9*'Kịch bản'!$B$8*B5 | C12: ='Tham số'!$B$9*'Kịch bản'!$C$8*C5 | D12: ='Tham số'!$B$9*'Kịch bản'!$D$8*D5 | E12: Lương BA × % tham gia × tháng
A13: Thiết kế giao diện | B13: ='Tham số'!$B$10*'Kịch bản'!$B$9*B5 | C13: ='Tham số'!$B$10*'Kịch bản'!$C$9*C5 | D13: ='Tham số'!$B$10*'Kịch bản'!$D$9*D5 | E13: Lương thiết kế × % tham gia × tháng
A14: Claude Code Max | B14: ='Tham số'!$B$13*'Kịch bản'!$B$10*B5 | C14: ='Tham số'!$B$13*'Kịch bản'!$C$10*C5 | D14: ='Tham số'!$B$13*'Kịch bản'!$D$10*D5 | E14: Số suất × giá suất × tháng
A15: Cộng phát triển | B15: =SUM(B11:B14) | C15: =SUM(C11:C14) | D15: =SUM(D11:D14)
A17: B. DUY TRÌ (hằng tháng sau khi hoàn thiện)
A18: Bảo trì (dev) | B18: ='Kịch bản'!$B$11*'Tham số'!$B$8 | C18: ='Kịch bản'!$C$11*'Tham số'!$B$8 | D18: ='Kịch bản'!$D$11*'Tham số'!$B$8 | E18: Ngày công bảo trì × đơn giá ngày dev
A19: BA thu góp ý, yêu cầu thay đổi | B19: ='Tham số'!$B$9*'Kịch bản'!$B$12 | C19: ='Tham số'!$B$9*'Kịch bản'!$C$12 | D19: ='Tham số'!$B$9*'Kịch bản'!$D$12 | E19: Lương BA × % khi duy trì
A20: Claude Code Max cho bảo trì | B20: ='Tham số'!$B$13*'Kịch bản'!$B$13 | C20: ='Tham số'!$B$13*'Kịch bản'!$C$13 | D20: ='Tham số'!$B$13*'Kịch bản'!$D$13 | E20: Số suất × giá suất
A21: Cộng duy trì / tháng | B21: =SUM(B18:B20) | C21: =SUM(C18:C20) | D21: =SUM(D18:D20)
A23: C. HẠ TẦNG
A24: Cloud chạy thật / tháng | B24: ='Hạ tầng'!$B$15*'Kịch bản'!$B$14 | C24: ='Hạ tầng'!$B$15*'Kịch bản'!$C$14 | D24: ='Hạ tầng'!$B$15*'Kịch bản'!$D$14 | E24: Cloud chuẩn × hệ số cấu hình
A25: Claude API / tháng (gợi ý + phân loại) | B25: ='Hạ tầng'!$B$30 | C25: ='Hạ tầng'!$B$30 | D25: ='Hạ tầng'!$B$30 | E25: Lưu lượng đã chốt — như nhau ở ba kịch bản
A26: Zalo OA + ZNS / tháng | B26: ='Hạ tầng'!$B$34+'Hạ tầng'!$B$35 | C26: ='Hạ tầng'!$B$34+'Hạ tầng'!$B$35 | D26: ='Hạ tầng'!$B$34+'Hạ tầng'!$B$35 | E26: 3 triệu/năm
A27: Cộng hạ tầng chạy thật / tháng | B27: =SUM(B24:B26) | C27: =SUM(C24:C26) | D27: =SUM(D24:D26)
A28: Hạ tầng trong giai đoạn phát triển (cả kỳ) | B28: =B24*'Hạ tầng'!$B$16*B5 | C28: =C24*'Hạ tầng'!$B$16*C5 | D28: =D24*'Hạ tầng'!$B$16*D5 | E28: Cloud chạy thật × % môi trường thử × tháng
A30: D. TỔNG
A31: Phát triển | B31: =B15 | C31: =C15 | D31: =D15 | E31: Mục A
A32: Duy trì năm đầu (12 tháng) | B32: =B21*12 | C32: =C21*12 | D32: =D21*12 | E32: Mục B × 12
A33: Hạ tầng năm đầu | B33: =B28+B27*12 | C33: =C28+C27*12 | D33: =D28+D27*12 | E33: Giai đoạn phát triển + 12 tháng chạy thật
A34: TỔNG NĂM ĐẦU | B34: =SUM(B31:B33) | C34: =SUM(C31:C33) | D34: =SUM(D31:D33) | E34: Phát triển + 12 tháng chạy thật
A36: Chi phí mỗi tháng sau khi hoàn thiện | B36: =B21+B27 | C36: =C21+C27 | D36: =D21+D27 | E36: Duy trì + hạ tầng
A37: Bình quân mỗi người dùng / tháng | B37: =IF('Hạ tầng'!$B$19=0,0,B36/'Hạ tầng'!$B$19) | C37: =IF('Hạ tầng'!$B$19=0,0,C36/'Hạ tầng'!$B$19) | D37: =IF('Hạ tầng'!$B$19=0,0,D36/'Hạ tầng'!$B$19) | E37: 30 người dùng
A38: Mỗi tháng trễ mốc tốn thêm | B38: =IF(B5=0,0,(B15+B28)/B5) | C38: =IF(C5=0,0,(C15+C28)/C5) | D38: =IF(D5=0,0,(D15+D28)/D5) | E38: Chi phí phát triển + hạ tầng thử, chia theo tháng
A40: Tham chiếu: làm theo cách thông thường, không dùng AI (2 dev)
A41: Thời gian (tháng) | C41: ='Khối lượng'!J70/('Tham số'!$B$7*'Tham số'!$B$5) | E41: Khối lượng ước lượng ÷ (2 dev × 22 ngày)
A42: Chi phí phát triển | C42: =('Tham số'!$B$6+'Tham số'!$B$9*'Kịch bản'!$C$8+'Tham số'!$B$10*'Kịch bản'!$C$9)*C41 | E42: (Lương dev + BA, thiết kế theo mức Trung bình) × thời gian; không có gói Claude

Sheet Tiến độ
A1: Timeline M1a → M4 theo ba kịch bản
A2: Ngày làm việc thứ Hai – thứ Sáu. Thứ tự: M1 (chỉ Zalo cá nhân) → M3 → M2 → M4 (các kênh khác). M1a và Khách hàng 360 theo số ngày ở sheet Kịch bản. M4 = số lượt kênh (2 dev làm song song) × ngày mỗi kênh. Thời gian còn lại chia cho M1b, M1c, M3, M2 theo tỷ lệ khối lượng ước lượng.
A3: Bắt đầu | B3: ='Tham số'!$B$4
A5: Mảnh | B5: Khối lượng ước lượng (ngày công, không AI) | C5: Lạc quan: ngày | D5: Bắt đầu | E5: Kết thúc | F5: Trung bình: ngày | G5: Bắt đầu | H5: Kết thúc | I5: Tiêu cực: ngày | J5: Bắt đầu | K5: Kết thúc
A6: M1a — Zalo cá nhân (máy chủ, danh bạ) | B6: ='Khối lượng'!J9 | C6: ='Kịch bản'!$B$6 | D6: =WORKDAY($B$3-1,1) | E6: =WORKDAY(D6,C6-1) | F6: ='Kịch bản'!$C$6 | G6: =WORKDAY($B$3-1,1) | H6: =WORKDAY(G6,F6-1) | I6: ='Kịch bản'!$D$6 | J6: =WORKDAY($B$3-1,1) | K6: =WORKDAY(J6,I6-1)
A7: M1b — Tổ chức, khách, 360 cơ bản · Zalo cá nhân | B7: ='Khối lượng'!J18 | C7: =ROUND(('Kịch bản'!$B$5-C$6-C$11)*B7/SUM($B$7:$B$10),0) | D7: =WORKDAY(E6,1) | E7: =WORKDAY(D7,C7-1) | F7: =ROUND(('Kịch bản'!$C$5-F$6-F$11)*B7/SUM($B$7:$B$10),0) | G7: =WORKDAY(H6,1) | H7: =WORKDAY(G7,F7-1) | I7: =ROUND(('Kịch bản'!$D$5-I$6-I$11)*B7/SUM($B$7:$B$10),0) | J7: =WORKDAY(K6,1) | K7: =WORKDAY(J7,I7-1)
A8: M1c — Bán hàng trong chat · Zalo cá nhân L4–L5 | B8: ='Khối lượng'!J26 | C8: =ROUND(('Kịch bản'!$B$5-C$6-C$11)*B8/SUM($B$7:$B$10),0) | D8: =WORKDAY(E7,1) | E8: =WORKDAY(D8,C8-1) | F8: =ROUND(('Kịch bản'!$C$5-F$6-F$11)*B8/SUM($B$7:$B$10),0) | G8: =WORKDAY(H7,1) | H8: =WORKDAY(G8,F8-1) | I8: =ROUND(('Kịch bản'!$D$5-I$6-I$11)*B8/SUM($B$7:$B$10),0) | J8: =WORKDAY(K7,1) | K8: =WORKDAY(J8,I8-1)
A9: M3 — 360 đủ, hóa đơn, app điện thoại · Zalo cá nhân | B9: ='Khối lượng'!J34 | C9: =ROUND(('Kịch bản'!$B$5-C$6-C$11)*B9/SUM($B$7:$B$10),0) | D9: =WORKDAY(E8,1) | E9: =WORKDAY(D9,C9-1) | F9: =ROUND(('Kịch bản'!$C$5-F$6-F$11)*B9/SUM($B$7:$B$10),0) | G9: =WORKDAY(H8,1) | H9: =WORKDAY(G9,F9-1) | I9: =ROUND(('Kịch bản'!$D$5-I$6-I$11)*B9/SUM($B$7:$B$10),0) | J9: =WORKDAY(K8,1) | K9: =WORKDAY(J9,I9-1)
A10: M2 — Phân luồng AI, giám sát · Zalo cá nhân L6–L7 | B10: ='Khối lượng'!J44 | C10: ='Kịch bản'!$B$5-C6-SUM(C7:C9)-C11 | D10: =WORKDAY(E9,1) | E10: =WORKDAY(D10,C10-1) | F10: ='Kịch bản'!$C$5-F6-SUM(F7:F9)-F11 | G10: =WORKDAY(H9,1) | H10: =WORKDAY(G10,F10-1) | I10: ='Kịch bản'!$D$5-I6-SUM(I7:I9)-I11 | J10: =WORKDAY(K9,1) | K10: =WORKDAY(J10,I10-1)
A11: M4 — Các kênh khác, mỗi kênh 4 ngày, 2 dev song song | B11: ='Khối lượng'!J68 | C11: =ROUNDUP('Kịch bản'!$B$16/'Tham số'!$B$7,0)*'Kịch bản'!$B$15 | D11: =WORKDAY(E10,1) | E11: =WORKDAY(D11,C11-1) | F11: =ROUNDUP('Kịch bản'!$C$16/'Tham số'!$B$7,0)*'Kịch bản'!$C$15 | G11: =WORKDAY(H10,1) | H11: =WORKDAY(G11,F11-1) | I11: =ROUNDUP('Kịch bản'!$D$16/'Tham số'!$B$7,0)*'Kịch bản'!$D$15 | J11: =WORKDAY(K10,1) | K11: =WORKDAY(J11,I11-1)
A12: Cộng / hoàn thành | B12: =SUM(B6:B11) | C12: =SUM(C6:C11) | E12: =E11 | F12: =SUM(F6:F11) | H12: =H11 | I12: =SUM(I6:I11) | K12: =K11
A13: Trong đó Khách hàng 360 (thuộc M1b) | C13: ='Kịch bản'!$B$7 | F13: ='Kịch bản'!$C$7 | I13: ='Kịch bản'!$D$7
A14: M1 xong (chạy thật cho đội VCparts) | E14: =E8 | H14: =H8 | K14: =K8
A15: Tốc độ cần so với không dùng AI (cả kỳ) | C15: =IF(C12=0,0,$B$12/(C12*'Tham số'!$B$7)) | F15: =IF(F12=0,0,$B$12/(F12*'Tham số'!$B$7)) | I15: =IF(I12=0,0,$B$12/(I12*'Tham số'!$B$7))
A16: Tốc độ cần: M1 → M2 (phần Zalo cá nhân, gồm M1a) | C16: =IF(SUM(C7:C10)=0,0,(SUM($B$7:$B$10)+$B$6)/((SUM(C7:C10)+C6)*'Tham số'!$B$7)) | F16: =IF(SUM(F7:F10)=0,0,(SUM($B$7:$B$10)+$B$6)/((SUM(F7:F10)+F6)*'Tham số'!$B$7)) | I16: =IF(SUM(I7:I10)=0,0,(SUM($B$7:$B$10)+$B$6)/((SUM(I7:I10)+I6)*'Tham số'!$B$7))
A17: Tốc độ cần: M4 (các kênh) | C17: =IF(C11=0,0,$B$11/(C11*'Tham số'!$B$7)) | F17: =IF(F11=0,0,$B$11/(F11*'Tham số'!$B$7)) | I17: =IF(I11=0,0,$B$11/(I11*'Tham số'!$B$7))
A18: Tốc độ cần = khối lượng ước lượng ÷ (ngày làm việc × số dev). Đo tốc độ thật sau M1a để kiểm chứng; các mảnh phụ thuộc bên ngoài (API VCsales, App Review Meta, baseline 2 tuần) không rút ngắn được bằng tốc độ code. M4 dồn mọi việc của kênh (kết nối, nhận/gửi, chatbot, chiến dịch, báo cáo kênh) vào 4 ngày mỗi kênh nên tốc độ cần ở M4 cao nhất.

Sheet Theo kênh
A1: Khối lượng theo kênh (BA tổng Phần II) × mảnh — ngày công ước lượng, không AI
A2: Tự cộng từ sheet Khối lượng theo cột Kênh và Mảnh.
A4: Kênh | B4: M1a | C4: M1b | D4: M1c | E4: M3 | F4: M2 | G4: M4 | H4: Cộng | I4: Tỷ trọng
A5: Nền tảng chung | B5: =SUMIFS('Khối lượng'!$J$4:$J$68,'Khối lượng'!$A$4:$A$68,"M1a",'Khối lượng'!$B$4:$B$68,$A5) | C5: =SUMIFS('Khối lượng'!$J$4:$J$68,'Khối lượng'!$A$4:$A$68,"M1b",'Khối lượng'!$B$4:$B$68,$A5) | D5: =SUMIFS('Khối lượng'!$J$4:$J$68,'Khối lượng'!$A$4:$A$68,"M1c",'Khối lượng'!$B$4:$B$68,$A5) | E5: =SUMIFS('Khối lượng'!$J$4:$J$68,'Khối lượng'!$A$4:$A$68,"M3",'Khối lượng'!$B$4:$B$68,$A5) | F5: =SUMIFS('Khối lượng'!$J$4:$J$68,'Khối lượng'!$A$4:$A$68,"M2",'Khối lượng'!$B$4:$B$68,$A5) | G5: =SUMIFS('Khối lượng'!$J$4:$J$68,'Khối lượng'!$A$4:$A$68,"M4",'Khối lượng'!$B$4:$B$68,$A5) | H5: =SUM(B5:G5) | I5: =IF($H$12=0,0,H5/$H$12)
A6: 11 Zalo cá nhân | B6: =SUMIFS('Khối lượng'!$J$4:$J$68,'Khối lượng'!$A$4:$A$68,"M1a",'Khối lượng'!$B$4:$B$68,$A6) | C6: =SUMIFS('Khối lượng'!$J$4:$J$68,'Khối lượng'!$A$4:$A$68,"M1b",'Khối lượng'!$B$4:$B$68,$A6) | D6: =SUMIFS('Khối lượng'!$J$4:$J$68,'Khối lượng'!$A$4:$A$68,"M1c",'Khối lượng'!$B$4:$B$68,$A6) | E6: =SUMIFS('Khối lượng'!$J$4:$J$68,'Khối lượng'!$A$4:$A$68,"M3",'Khối lượng'!$B$4:$B$68,$A6) | F6: =SUMIFS('Khối lượng'!$J$4:$J$68,'Khối lượng'!$A$4:$A$68,"M2",'Khối lượng'!$B$4:$B$68,$A6) | G6: =SUMIFS('Khối lượng'!$J$4:$J$68,'Khối lượng'!$A$4:$A$68,"M4",'Khối lượng'!$B$4:$B$68,$A6) | H6: =SUM(B6:G6) | I6: =IF($H$12=0,0,H6/$H$12)
A7: 12 Facebook cá nhân | B7: =SUMIFS('Khối lượng'!$J$4:$J$68,'Khối lượng'!$A$4:$A$68,"M1a",'Khối lượng'!$B$4:$B$68,$A7) | C7: =SUMIFS('Khối lượng'!$J$4:$J$68,'Khối lượng'!$A$4:$A$68,"M1b",'Khối lượng'!$B$4:$B$68,$A7) | D7: =SUMIFS('Khối lượng'!$J$4:$J$68,'Khối lượng'!$A$4:$A$68,"M1c",'Khối lượng'!$B$4:$B$68,$A7) | E7: =SUMIFS('Khối lượng'!$J$4:$J$68,'Khối lượng'!$A$4:$A$68,"M3",'Khối lượng'!$B$4:$B$68,$A7) | F7: =SUMIFS('Khối lượng'!$J$4:$J$68,'Khối lượng'!$A$4:$A$68,"M2",'Khối lượng'!$B$4:$B$68,$A7) | G7: =SUMIFS('Khối lượng'!$J$4:$J$68,'Khối lượng'!$A$4:$A$68,"M4",'Khối lượng'!$B$4:$B$68,$A7) | H7: =SUM(B7:G7) | I7: =IF($H$12=0,0,H7/$H$12)
A8: 13 Zalo OA | B8: =SUMIFS('Khối lượng'!$J$4:$J$68,'Khối lượng'!$A$4:$A$68,"M1a",'Khối lượng'!$B$4:$B$68,$A8) | C8: =SUMIFS('Khối lượng'!$J$4:$J$68,'Khối lượng'!$A$4:$A$68,"M1b",'Khối lượng'!$B$4:$B$68,$A8) | D8: =SUMIFS('Khối lượng'!$J$4:$J$68,'Khối lượng'!$A$4:$A$68,"M1c",'Khối lượng'!$B$4:$B$68,$A8) | E8: =SUMIFS('Khối lượng'!$J$4:$J$68,'Khối lượng'!$A$4:$A$68,"M3",'Khối lượng'!$B$4:$B$68,$A8) | F8: =SUMIFS('Khối lượng'!$J$4:$J$68,'Khối lượng'!$A$4:$A$68,"M2",'Khối lượng'!$B$4:$B$68,$A8) | G8: =SUMIFS('Khối lượng'!$J$4:$J$68,'Khối lượng'!$A$4:$A$68,"M4",'Khối lượng'!$B$4:$B$68,$A8) | H8: =SUM(B8:G8) | I8: =IF($H$12=0,0,H8/$H$12)
A9: 14 Fanpage | B9: =SUMIFS('Khối lượng'!$J$4:$J$68,'Khối lượng'!$A$4:$A$68,"M1a",'Khối lượng'!$B$4:$B$68,$A9) | C9: =SUMIFS('Khối lượng'!$J$4:$J$68,'Khối lượng'!$A$4:$A$68,"M1b",'Khối lượng'!$B$4:$B$68,$A9) | D9: =SUMIFS('Khối lượng'!$J$4:$J$68,'Khối lượng'!$A$4:$A$68,"M1c",'Khối lượng'!$B$4:$B$68,$A9) | E9: =SUMIFS('Khối lượng'!$J$4:$J$68,'Khối lượng'!$A$4:$A$68,"M3",'Khối lượng'!$B$4:$B$68,$A9) | F9: =SUMIFS('Khối lượng'!$J$4:$J$68,'Khối lượng'!$A$4:$A$68,"M2",'Khối lượng'!$B$4:$B$68,$A9) | G9: =SUMIFS('Khối lượng'!$J$4:$J$68,'Khối lượng'!$A$4:$A$68,"M4",'Khối lượng'!$B$4:$B$68,$A9) | H9: =SUM(B9:G9) | I9: =IF($H$12=0,0,H9/$H$12)
A10: 15 Email | B10: =SUMIFS('Khối lượng'!$J$4:$J$68,'Khối lượng'!$A$4:$A$68,"M1a",'Khối lượng'!$B$4:$B$68,$A10) | C10: =SUMIFS('Khối lượng'!$J$4:$J$68,'Khối lượng'!$A$4:$A$68,"M1b",'Khối lượng'!$B$4:$B$68,$A10) | D10: =SUMIFS('Khối lượng'!$J$4:$J$68,'Khối lượng'!$A$4:$A$68,"M1c",'Khối lượng'!$B$4:$B$68,$A10) | E10: =SUMIFS('Khối lượng'!$J$4:$J$68,'Khối lượng'!$A$4:$A$68,"M3",'Khối lượng'!$B$4:$B$68,$A10) | F10: =SUMIFS('Khối lượng'!$J$4:$J$68,'Khối lượng'!$A$4:$A$68,"M2",'Khối lượng'!$B$4:$B$68,$A10) | G10: =SUMIFS('Khối lượng'!$J$4:$J$68,'Khối lượng'!$A$4:$A$68,"M4",'Khối lượng'!$B$4:$B$68,$A10) | H10: =SUM(B10:G10) | I10: =IF($H$12=0,0,H10/$H$12)
A11: 16 Kênh sau này | B11: =SUMIFS('Khối lượng'!$J$4:$J$68,'Khối lượng'!$A$4:$A$68,"M1a",'Khối lượng'!$B$4:$B$68,$A11) | C11: =SUMIFS('Khối lượng'!$J$4:$J$68,'Khối lượng'!$A$4:$A$68,"M1b",'Khối lượng'!$B$4:$B$68,$A11) | D11: =SUMIFS('Khối lượng'!$J$4:$J$68,'Khối lượng'!$A$4:$A$68,"M1c",'Khối lượng'!$B$4:$B$68,$A11) | E11: =SUMIFS('Khối lượng'!$J$4:$J$68,'Khối lượng'!$A$4:$A$68,"M3",'Khối lượng'!$B$4:$B$68,$A11) | F11: =SUMIFS('Khối lượng'!$J$4:$J$68,'Khối lượng'!$A$4:$A$68,"M2",'Khối lượng'!$B$4:$B$68,$A11) | G11: =SUMIFS('Khối lượng'!$J$4:$J$68,'Khối lượng'!$A$4:$A$68,"M4",'Khối lượng'!$B$4:$B$68,$A11) | H11: =SUM(B11:G11) | I11: =IF($H$12=0,0,H11/$H$12)
A12: Cộng | B12: =SUM(B5:B11) | C12: =SUM(C5:C11) | D12: =SUM(D5:D11) | E12: =SUM(E5:E11) | F12: =SUM(F5:F11) | G12: =SUM(G5:G11) | H12: =SUM(H5:H11) | I12: =SUM(I5:I11)
A13: Kiểm tra (= tổng sheet Khối lượng) | H13: =H12-'Khối lượng'!J70

Sheet Kịch bản
A1: Thông số ba kịch bản
A3: Thông số | B3: Lạc quan | C3: Trung bình | D3: Tiêu cực | E3: Đơn vị | F3: Ghi chú
A4: Thời gian hoàn thiện M1a → M4 | B4: 2 | C4: 3 | D4: 4 | E4: tháng | F4: Lạc quan = mốc chủ dự án (chốt 04/10/2026)
A5: Ngày làm việc | B5: =B4*'Tham số'!$B$5 | C5: =C4*'Tham số'!$B$5 | D5: =D4*'Tham số'!$B$5 | E5: ngày | F5: Tháng × ngày làm việc/tháng
A6: Zalo cá nhân (M1a) | B6: 3 | C6: 5 | D6: 8 | E6: ngày | F6: Lạc quan = mốc chủ dự án
A7: Khách hàng 360 (nằm trong M1b) | B7: 2 | C7: 3 | D7: 5 | E7: ngày | F7: Lạc quan = mốc chủ dự án. Bản cơ bản: hồ sơ, dòng thời gian, liên kết mã KH
A8: BA tham gia trong phát triển | B8: 0.5 | C8: 0.75 | D8: 1 | E8: % thời gian | F8: Đặc tả 00–07 đã có; BA bổ sung theo góp ý, UAT, làm việc với người dùng
A9: Thiết kế giao diện tham gia | B9: 0.25 | C9: 0.5 | D9: 0.75 | E9: % thời gian | F9: TK1 đã chốt; còn TK2 và màn mới (MH-SZ-15, MH-OA-20, điện thoại)
A10: Suất Claude Code Max khi phát triển | B10: 3 | C10: 3 | D10: 3 | E10: suất | F10: 2 dev + 1 BA/thiết kế
A11: Ngày công bảo trì mỗi tháng | B11: 5 | C11: 8 | D11: 12 | E11: ngày/tháng | F11: Sửa bảng ánh xạ khi Zalo đổi, sự cố, hỗ trợ người dùng
A12: BA khi duy trì | B12: 0.1 | C12: 0.2 | D12: 0.3 | E12: % thời gian | F12: Thu góp ý, viết yêu cầu thay đổi
A13: Suất Claude Code Max khi duy trì | B13: 1 | C13: 1 | D13: 2 | E13: suất
A14: Hệ số cấu hình cloud | B14: 0.85 | C14: 1 | D14: 1.3 | E14: hệ số | F14: Nhân với báo giá cloud ở sheet Hạ tầng; tiêu cực = phải nâng cấu hình
A15: Ngày cho mỗi kênh ở M4 | B15: 4 | C15: 5 | D15: 6 | E15: ngày | F15: Lạc quan = mốc chủ dự án (chốt 04/10/2026): mỗi kênh 4 ngày, 2 dev làm song song 2 kênh
A16: Số kênh ở M4 | B16: 9 | C16: 9 | D16: 9 | E16: kênh | F16: Zalo OA (cả ZNS), Fanpage, Facebook cá nhân, Email, chatbot/livechat web, TikTok Shop, Shopee, Instagram, tổng đài. Không bật FB cá nhân thì giảm 1

Sheet Tham số
A1: Tham số dùng chung
A3: Tham số | B3: Giá trị | C3: Đơn vị | D3: Nguồn / ghi chú
A4: Ngày bắt đầu | B4: 46300 | C4: ngày | D4: Thứ Hai sau ngày chốt 04/10/2026
A5: Ngày làm việc mỗi tháng | B5: 22 | C5: ngày | D5: Thứ Hai – thứ Sáu
A6: Lương đội dev | B6: 75000000 | C6: VNĐ/tháng | D6: Chốt 04/10/2026: 2 dev, đã gồm mọi khoản (bảo hiểm, phụ cấp)
A7: Số dev | B7: 2 | C7: người | D7: Chốt 04/10/2026; dev kiêm FE, BE, QA, DevOps cùng Claude Code
A8: Đơn giá một ngày công dev | B8: =$B$6/$B$7/$B$5 | C8: VNĐ/ngày | D8: Công thức
A9: Lương BA (toàn thời gian) | B9: 25000000 | C9: VNĐ/tháng | D9: Giả định, đã gồm mọi khoản. BA viết đặc tả, UAT, đọc góp ý, làm việc với chủ dự án; làm cùng Claude
A10: Lương thiết kế giao diện (toàn thời gian) | B10: 20000000 | C10: VNĐ/tháng | D10: Giả định. Thiết kế canvas theo đặc tả, sửa theo góp ý; làm cùng Claude
A11: Gói Claude Code Max 20x | B11: 200 | C11: USD/suất/tháng | D11: claude.com/pricing (04/10/2026): Max 5x từ 100 USD, Max 20x 200 USD
A12: Tỷ giá USD → VNĐ | B12: 26500 | C12: VNĐ/USD | D12: Giả định; cập nhật theo ngân hàng khi chốt
A13: Một suất Claude Code Max | B13: =$B$11*$B$12 | C13: VNĐ/tháng | D13: Công thức
A14: Claude Sonnet 5.5 — input | B14: 2 | C14: USD/1M token | D14: Bảng giá Anthropic API (25/09/2026)
A15: Claude Sonnet 5.5 — đọc cache | B15: 0.2 | C15: USD/1M token | D15: Bảng giá Anthropic API
A16: Claude Sonnet 5.5 — output | B16: 10 | C16: USD/1M token | D16: Bảng giá Anthropic API
A17: Claude Haiku 4.5 — input | B17: 1 | C17: USD/1M token | D17: Bảng giá Anthropic API
A18: Claude Haiku 4.5 — output | B18: 5 | C18: USD/1M token | D18: Bảng giá Anthropic API

Sheet Hạ tầng
A1: Hạ tầng cloud và dịch vụ (VNĐ/tháng, môi trường chạy thật)
A2: Chốt 04/10/2026: thuê cloud toàn bộ. Báo giá là giả định theo mặt bằng cloud trong nước (Viettel IDC, FPT, VNG, Bizfly); ưu tiên đặt dữ liệu tại Việt Nam theo NĐ 13. Chờ báo giá thật.
A4: Khoản | B4: Giá trị | C4: Đơn vị | D4: Ghi chú
A5: A. Cloud
A6: Máy ảo ứng dụng: API, web, worker, Redis (4 vCPU, 8 GB) | B6: 1800000 | C6: VNĐ/tháng | D6: NestJS API, Dashboard, BullMQ
A7: MongoDB: máy ảo 4 vCPU, 8 GB, SSD 200 GB, mã hóa ổ đĩa | B7: 2200000 | C7: VNĐ/tháng | D7: Mã hóa at-rest theo CLAUDE.md §12
A8: Lưu trữ đối tượng 500 GB (thay MinIO) | B8: 600000 | C8: VNĐ/tháng | D8: File, ảnh, ghi âm
A9: Máy ảo Chrome driver: 8 vCPU, 16 GB, có giao diện đồ họa | B9: 3500000 | C9: VNĐ/tháng | D9: 10–15 nick Zalo cá nhân. Rủi ro: Zalo có thể nghi ngờ IP trung tâm dữ liệu — thử ở M1a
A10: Máy ảo Chrome driver dự phòng (để tắt, chỉ trả ổ đĩa) | B10: 300000 | C10: VNĐ/tháng | D10: R8-01: bật lên khi máy chính hỏng
A11: Máy ảo ASR faster-whisper (8 vCPU, 16 GB, chạy CPU) | B11: 2800000 | C11: VNĐ/tháng | D11: Hoặc GPU thuê theo giờ nếu lượng ghi âm lớn
A12: Sao lưu, snapshot hằng ngày | B12: 600000 | C12: VNĐ/tháng
A13: Băng thông, IP tĩnh | B13: 300000 | C13: VNĐ/tháng
A14: Tên miền, Cloudflare, chứng chỉ | B14: 200000 | C14: VNĐ/tháng
A15: Cộng cloud (cấu hình chuẩn) | B15: =SUM(B6:B14) | C15: VNĐ/tháng | D15: Nhân hệ số cấu hình của từng kịch bản
A16: Môi trường thử trong giai đoạn phát triển | B16: 0.5 | C16: % cloud thật | D16: Cấu hình nhỏ hơn, chưa cần máy dự phòng
A18: B. Claude API (lưu lượng đã chốt 04/10/2026)
A19: Số người dùng | B19: 30 | C19: người | D19: Chốt
A20: Tin nhắn vào mỗi ngày (mọi kênh) | B20: 3000 | C20: tin/ngày | D20: Chốt
A21: Số ngày mỗi tháng | B21: 30 | C21: ngày
A22: Tỷ lệ tin cần soạn nháp | B22: 0.4 | C22: % | D22: Chốt
A23: Token input mỗi lượt gợi ý (Sonnet 5.5) | B23: 8000 | C23: token | D23: 30 tin gần nhất + hồ sơ + thẻ VCwiki + tra VCsales + playbook
A24: Tỷ lệ input đọc từ cache | B24: 0.5 | C24: % | D24: Playbook, system prompt cố định
A25: Token output mỗi lượt | B25: 400 | C25: token
A26: Gợi ý trả lời / tháng | B26: =$B$20*$B$21*$B$22*($B$23*(1-$B$24)*'Tham số'!$B$14+$B$23*$B$24*'Tham số'!$B$15+$B$25*'Tham số'!$B$16)/1000000 | C26: USD/tháng | D26: Công thức
A27: Token input phân loại mỗi tin (Haiku 4.5) | B27: 1500 | C27: token
A28: Token output phân loại mỗi tin | B28: 100 | C28: token
A29: Phân loại tin / tháng | B29: =$B$20*$B$21*($B$27*'Tham số'!$B$17+$B$28*'Tham số'!$B$18)/1000000 | C29: USD/tháng | D29: Công thức
A30: Cộng Claude API | B30: =($B$26+$B$29)*'Tham số'!$B$12 | C30: VNĐ/tháng | D30: Công thức
A32: C. Kênh
A33: Gói Zalo OA | B33: 3000000 | C33: VNĐ/năm | D33: Chốt 04/10/2026
A34: Gói Zalo OA quy ra tháng | B34: =$B$33/12 | C34: VNĐ/tháng | D34: Công thức
A35: Tin ZNS | B35: 0 | C35: VNĐ/tháng | D35: Chưa bật; nhập khi có kế hoạch gửi ZNS (M2)

Sheet Khối lượng
A1: Khối lượng theo mảnh — ngày công ước lượng nếu KHÔNG dùng AI
A2: Dùng để chia thời gian giữa các mảnh (sheet Tiến độ) và tính tốc độ cần so với cách làm thông thường. Không dùng để tính tiền. M1 → M3 → M2 chỉ làm trên Zalo cá nhân; mọi kênh khác dồn sang M4 (chốt 04/10/2026).
A3: Mảnh | B3: Kênh (BA tổng Phần II) | C3: Hạng mục | D3: BA | E3: Thiết kế | F3: Frontend | G3: Backend | H3: QA | I3: DevOps | J3: Tổng ngày công | K3: Căn cứ đặc tả
A4: M1a | B4: 11 Zalo cá nhân | C4: Máy chủ Chrome driver trên cloud, 10–15 nick, cảnh báo phiên rớt (R8-01) | D4: 1 | E4: 0 | F4: 2 | G4: 4 | H4: 2 | I4: 5 | J4: =SUM(D4:I4) | K4: BA §19, D8-08; docs/chrome-driver.md
A5: M1a | B5: 11 Zalo cá nhân | C5: Trạng thái nick và Đồng bộ (góc sale của /sync) | D5: 1 | E5: 1 | F5: 3 | G5: 3 | H5: 2 | I5: 0 | J5: =SUM(D5:I5) | K5: 03 MH-SZ-12
A6: M1a | B6: 11 Zalo cá nhân | C6: Danh bạ, lời mời kết bạn (L3) | D6: 1 | E6: 1 | F6: 4 | G6: 4 | H6: 2 | I6: 0 | J6: =SUM(D6:I6) | K6: BA §11.6 L3; 03 MH-SZ-07, 09
A7: M1a | B7: 11 Zalo cá nhân | C7: Thu hồi tin, mã tin nhóm, giới hạn tần suất | D7: 0.5 | E7: 0 | F7: 1 | G7: 5 | H7: 2 | I7: 0 | J7: =SUM(D7:I7) | K7: VCL-INT-11
A8: M1a | B8: 11 Zalo cá nhân | C8: Hồi quy và UAT phân hệ VC Zalo | D8: 2 | E8: 0 | F8: 0 | G8: 0 | H8: 6 | I8: 0 | J8: =SUM(D8:I8) | K8: 03 UAT-SZ (99 ca)
A9: M1a | C9: Cộng M1a | D9: =SUM(D4:D8) | E9: =SUM(E4:E8) | F9: =SUM(F4:F8) | G9: =SUM(G4:G8) | H9: =SUM(H4:H8) | I9: =SUM(I4:I8) | J9: =SUM(J4:J8)
A11: M1b | B11: Nền tảng chung | C11: Khung ứng dụng chung: điều hướng, thông báo, Ctrl+K, /me, trang lỗi | D11: 1 | E11: 3 | F11: 8 | G11: 4 | H11: 4 | I11: 0 | J11: =SUM(D11:I11) | K11: 00 MH-UI-01…06
A12: M1b | B12: Nền tảng chung | C12: Cây tổ chức, vai trò, ma trận quyền, quyền tạm thời, nhật ký | D12: 3 | E12: 3 | F12: 10 | G12: 12 | H12: 8 | I12: 0 | J12: =SUM(D12:I12) | K12: 01 MH-PQ (15 màn, 124 ca UAT)
A13: M1b | B13: Nền tảng chung | C13: Owner, chia hội thoại, bàn giao, trực thay | D13: 2 | E13: 2 | F13: 6 | G13: 8 | H13: 5 | I13: 0 | J13: =SUM(D13:I13) | K13: BA 5.5; 03 QT-SZ-10/11
A14: M1b | B14: Nền tảng chung | C14: Khách hàng 360 cơ bản: hồ sơ, gộp theo D8-05, liên kết mã KH | D14: 2 | E14: 2 | F14: 6 | G14: 8 | H14: 5 | I14: 0 | J14: =SUM(D14:I14) | K14: 02 MH-DK-01…03, 09, 10
A15: M1b | B15: Nền tảng chung | C15: Nạp danh mục khách từ VCsales | D15: 1 | E15: 0 | F15: 0 | G15: 5 | H15: 2 | I15: 0 | J15: =SUM(D15:I15) | K15: D3-09
A16: M1b | B16: Nền tảng chung | C16: Nền bảo mật: cổng mức mật, khóa theo khách, tenant_id, connector 24/7 | D16: 1 | E16: 0 | F16: 0 | G16: 12 | H16: 4 | I16: 4 | J16: =SUM(D16:I16) | K16: BA §2.2
A17: M1b | B17: Nền tảng chung | C17: Đo baseline KPI | D17: 1 | E17: 0 | F17: 0 | G17: 2 | H17: 1 | I17: 0 | J17: =SUM(D17:I17) | K17: D2-17
A18: M1b | C18: Cộng M1b | D18: =SUM(D11:D17) | E18: =SUM(E11:E17) | F18: =SUM(F11:F17) | G18: =SUM(G11:G17) | H18: =SUM(H11:H17) | I18: =SUM(I11:I17) | J18: =SUM(J11:J17)
A20: M1c | B20: Nền tảng chung | C20: Tra giá, tồn, gửi báo giá VCsales (adapter ERP) | D20: 2 | E20: 2 | F20: 6 | G20: 10 | H20: 5 | I20: 0 | J20: =SUM(D20:I20) | K20: F9.1, F9.2, F9.5–F9.7; phụ thuộc TT-01
A21: M1c | B21: Nền tảng chung | C21: Phiếu báo giá / hậu mãi, hàng việc CSKH, vòng NVKD duyệt ⇄ trả lại | D21: 2 | E21: 2 | F21: 6 | G21: 6 | H21: 4 | I21: 0 | J21: =SUM(D21:I21) | K21: D9; 03 MH-SZ-15, 04 MH-OA-20
A22: M1c | B22: Nền tảng chung | C22: Gợi ý trả lời AI (worker suggest, playbook, chống prompt injection) | D22: 1 | E22: 0 | F22: 3 | G22: 8 | H22: 4 | I22: 0 | J22: =SUM(D22:I22) | K22: CLAUDE.md §8; F7.3
A23: M1c | B23: Nền tảng chung | C23: Ghi âm → chữ, đính kèm lên kho file, tìm kiếm toàn văn | D23: 1 | E23: 0 | F23: 3 | G23: 8 | H23: 3 | I23: 2 | J23: =SUM(D23:I23) | K23: BA 5.3
A24: M1c | B24: Nền tảng chung | C24: Báo cáo cơ bản | D24: 1 | E24: 2 | F24: 5 | G24: 5 | H24: 3 | I24: 0 | J24: =SUM(D24:I24) | K24: 07 MH-BC (phần cơ bản)
A25: M1c | B25: 11 Zalo cá nhân | C25: Zalo cá nhân L4–L5: thông báo realtime, panel thông tin + kho media, tìm trong hội thoại, video, vị trí, cuộc gọi | D25: 1 | E25: 1 | F25: 4 | G25: 5 | H25: 3 | I25: 0 | J25: =SUM(D25:I25) | K25: BA §11.6 L4, L5; 03 MH-SZ-10, 11, 14
A26: M1c | C26: Cộng M1c | D26: =SUM(D20:D25) | E26: =SUM(E20:E25) | F26: =SUM(F20:F25) | G26: =SUM(G20:G25) | H26: =SUM(H20:H25) | I26: =SUM(I20:I25) | J26: =SUM(J20:J25)
A28: M3 | B28: Nền tảng chung | C28: Khách hàng 360 đủ: khối thương mại, C3 qua adapter, theo dõi báo giá, nhắc mua lại | D28: 3 | E28: 3 | F28: 8 | G28: 12 | H28: 6 | I28: 0 | J28: =SUM(D28:I28) | K28: BR18, F9.8, F8.4
A29: M3 | B29: Nền tảng chung | C29: Hóa đơn VAT (VCinvoice) và công nợ | D29: 2 | E29: 3 | F29: 8 | G29: 10 | H29: 6 | I29: 0 | J29: =SUM(D29:I29) | K29: 06 MH-HD-01…13
A30: M3 | B30: Nền tảng chung | C30: VCdms trong VCsales | D30: 1 | E30: 0 | F30: 3 | G30: 6 | H30: 3 | I30: 0 | J30: =SUM(D30:I30) | K30: F9.10, F9.12, F9.13
A31: M3 | B31: Nền tảng chung | C31: MCP cho nhân viên | D31: 1 | E31: 0 | F31: 0 | G31: 6 | H31: 3 | I31: 0 | J31: =SUM(D31:I31) | K31: BA §1.2
A32: M3 | B32: Nền tảng chung | C32: App điện thoại | D32: 3 | E32: 8 | F32: 30 | G32: 5 | H32: 10 | I32: 0 | J32: =SUM(D32:I32) | K32: QĐ-01 chưa chốt
A33: M3 | B33: Nền tảng chung | C33: AI chạy tại chỗ cho dữ liệu C3 | D33: 1 | E33: 0 | F33: 0 | G33: 8 | H33: 2 | I33: 4 | J33: =SUM(D33:I33) | K33: BA §19 M3
A34: M3 | C34: Cộng M3 | D34: =SUM(D28:D33) | E34: =SUM(E28:E33) | F34: =SUM(F28:F33) | G34: =SUM(G28:G33) | H34: =SUM(H28:H33) | I34: =SUM(I28:I33) | J34: =SUM(J28:J33)
A36: M2 | B36: Nền tảng chung | C36: Phân loại AI → phiếu việc, cảm xúc, leo thang, AI tự tạo phiếu báo giá | D36: 3 | E36: 2 | F36: 6 | G36: 12 | H36: 6 | I36: 0 | J36: =SUM(D36:I36) | K36: F9.14, D9-05
A37: M2 | B37: Nền tảng chung | C37: NĐ 13 vận hành, xuất dữ liệu | D37: 1 | E37: 0 | F37: 3 | G37: 5 | H37: 3 | I37: 0 | J37: =SUM(D37:I37) | K37: 01 MH-PQ-12…14
A38: M2 | B38: Nền tảng chung | C38: Bật VCsoft, VCe | D38: 1 | E38: 0 | F38: 0 | G38: 2 | H38: 2 | I38: 1 | J38: =SUM(D38:I38) | K38: D5-11
A39: M2 | B39: 11 Zalo cá nhân | C39: Zalo cá nhân L6–L7: nhóm chat, gán nhãn, thu hồi, chuyển tiếp, thả cảm xúc | D39: 1 | E39: 1 | F39: 4 | G39: 5 | H39: 3 | I39: 0 | J39: =SUM(D39:I39) | K39: BA §11.6 L6, L7
A40: M2 | B40: Nền tảng chung | C40: Dashboard đủ, báo cáo tháng, so sánh nhóm, phân tích liên kênh | D40: 2 | E40: 3 | F40: 6 | G40: 4 | H40: 3 | I40: 0 | J40: =SUM(D40:I40) | K40: 07; BA §19 M4
A41: M2 | B41: Nền tảng chung | C41: Kèm cặp, hội thoại mẫu sang VCwiki | D41: 1 | E41: 1 | F41: 2 | G41: 3 | H41: 2 | I41: 0 | J41: =SUM(D41:I41) | K41: F15.13
A42: M2 | B42: Nền tảng chung | C42: Deal VCedu / B2B, tenant không ERP | D42: 2 | E42: 2 | F42: 6 | G42: 10 | H42: 5 | I42: 2 | J42: =SUM(D42:I42) | K42: D5-14
A43: M2 | B43: 11 Zalo cá nhân | C43: Zalo cá nhân: L7 còn lại (quản trị nhóm nâng cao, định dạng tin); giám sát nick: nhịp gửi, phiên rớt, tỷ lệ trả lời | D43: 1 | E43: 1 | F43: 3 | G43: 4 | H43: 2 | I43: 0 | J43: =SUM(D43:I43) | K43: BA §11.6 L7
A44: M2 | C44: Cộng M2 | D44: =SUM(D36:D43) | E44: =SUM(E36:E43) | F44: =SUM(F36:F43) | G44: =SUM(G36:G43) | H44: =SUM(H36:H43) | I44: =SUM(I36:I43) | J44: =SUM(J36:J43)
...
